Workbook

Sheet Meslek Sayi
A1: № | B1: Професий / meslek | C1: Кол-во / sayi | D1: Total | E1: =+C80 -> 25
A2: 1 | B2: ALCI BOYA USTASI | C2: =COUNTIF(IPPODROM!E:E,'Meslek Sayi'!B:B) -> 0
A3: 2 | B3: ALCIPAN USTASI | C3: =COUNTIF(IPPODROM!E:E,'Meslek Sayi'!B:B) -> 0
A4: 3 | B4: ALET OPERATORU | C4: =COUNTIF(IPPODROM!E:E,'Meslek Sayi'!B:B) -> 0
A5: 4 | B5: AMBAR SEFI | C5: =COUNTIF(IPPODROM!E:E,'Meslek Sayi'!B:B) -> 0
A6: 5 | B6: AMBARCI | C6: =COUNTIF(IPPODROM!E:E,'Meslek Sayi'!B:B) -> 0
A7: 6 | B7: BAS MIMAR | C7: =COUNTIF(IPPODROM!E:E,'Meslek Sayi'!B:B) -> 3
A8: 7 | B8: BAS MUHASEBECI | C8: =COUNTIF(IPPODROM!E:E,'Meslek Sayi'!B:B) -> 0
A9: 8 | B9: BAS MUHENDIS MEKANIK | C9: =COUNTIF(IPPODROM!E:E,'Meslek Sayi'!B:B) -> 0
A10: 9 | B10: BEKCI | C10: =COUNTIF(IPPODROM!E:E,'Meslek Sayi'!B:B) -> 0
A11: 10 | B11: BEKCI SORUMLUSU | C11: =COUNTIF(IPPODROM!E:E,'Meslek Sayi'!B:B) -> 0
A12: 11 | B12: BETONCU | C12: =COUNTIF(IPPODROM!E:E,'Meslek Sayi'!B:B) -> 0
A13: 12 | B13: BOLUM BASKANI | C13: =COUNTIF(IPPODROM!E:E,'Meslek Sayi'!B:B) -> 0
... A79: 78 | B79: SAPCI | C79: =COUNTIF(IPPODROM!E:E,'Meslek Sayi'!B:B) -> 0
A80: TOPLAM SAYI | C80: =SUM(C2:C79) -> 25

Sheet Cover page 
B2: МОНАРТ / ИППОДРОМ | H2: =+IPPODROM!I1 -> Суббота
H3: =+IPPODROM!I2 -> 46123
B4: № | C4: Персонал / Personnel | D4: Общий Кадров | E4: НЕ ВЫШЛИ НА РАБОТУ | F4: Бальничный ОТПУСК / Командировка | G4: ОБЩЕЕ
B5: A | C5: РАБОЧИЕ / PRODUCTIVE PERSONEL LIST | D5: General Staff | E5: Out of Working Staff | F5: Leave / Holiday / Sick | G5: TOTAL
B6: 1 | C6: ТЕХНИКА БЕЗОПАСНОСТИ / GUVENLIK | D6: ='GUNLUK RAPOR'!D3 -> 2 | E6: ='GUNLUK RAPOR'!I3 -> 1 | F6: ='GUNLUK RAPOR'!J3 -> 0 | G6: =D6-E6-F6 -> 1
B7: 1 | C7: INCE ISLER-AKBARALI | D7: ='GUNLUK RAPOR'!D4 -> 1 | E7: ='GUNLUK RAPOR'!I4 -> 0 | F7: ='GUNLUK RAPOR'!J4 -> 1 | G7: =D7-E7-F7 -> 0
C8: PRODUCTIVE LABOUR | D8: =SUM(D6:D7) -> 3 | E8: =SUM(E6:E7) -> 1 | F8: =SUM(F6:F7) -> 1 | G8: =SUM(G6:G7) -> 1 | K8: Santiyede Calisan | L8: Yok ve Izin | M8: Dis Gorev | N8: Toplam
B9: B | C9: ИТР / UNPRODUCTIVE PERSONEL LIST | D9: General Staff | E9: Out of Working Staff | F9: Leave / Holiday / Sick | G9: TOTAL
B10: 1 | C10: РУКОВОДИТЕЛЬ ПРОЕКТА / PROJECT MANAGER | D10: =+N10 -> 0 | E10: =L10 -> 0 | F10: =M10 -> 0 | G10: =D10-E10-F10 -> 0 | K10: =+G10 -> 0
B11: 2 | C11: ЗАМЕСТИТЕЛЬ РУКОВОДИТЕЛЯ ПРОЕКТА / ASS PROJECT MANAGER | D11: =+N11 -> 2 | E11: =L11 -> 0 | F11: =M11 -> 0 | G11: =D11-E11-F11 -> 2 | K11: =+G11 -> 2 | L11: =+IPPODROM!J3+IPPODROM!J4 -> 0 | M11: =+IPPODROM!M3+IPPODROM!M4 -> 0 | N11: =+IPPODROM!N3+IPPODROM!N4 -> 2
B12: 3 | C12: НАЧАЛЬНИК УЧАСТКА / SITE MANAGER | D12: =+N12 -> 2 | E12: =L12 -> 0 | F12: =M12 -> 1 | G12: =D12-E12-F12 -> 1 | K12: =+G12 -> 1 | L12: =IPPODROM!J8+IPPODROM!J9 -> 0 | M12: =IPPODROM!M8+IPPODROM!M9 -> 1 | N12: =IPPODROM!N8+IPPODROM!N9 -> 2
B13: 4 | C13: НАЧАЛЬНИК ТЕХОФИСА /TEKNIK OFIS | D13: =+N13 -> 0 | E13: =L13 -> 0 | F13: =M13 -> 0 | G13: =D13-E13-F13 -> 0 | K13: =+G13 -> 0
B14: 5 | C14: АРХИТЕКТОР / MIMAR | D14: =+N14 -> 3 | E14: =L14 -> 0 | F14: =M14 -> 0 | G14: =D14-E14-F14 -> 3 | K14: =+G14 -> 3 | L14: =+IPPODROM!J5+IPPODROM!J6+IPPODROM!J7 -> 0 | M14: =+IPPODROM!M5+IPPODROM!M6+IPPODROM!M7 -> 0 | N14: =+IPPODROM!N5+IPPODROM!N6+IPPODROM!N7 -> 3
B15: 6 | C15: ИНЖЕНЕР СТРОИТЕЛЬ / INSAAT TEKNIKERI | D15: =+N15 -> 13 | E15: =L15 -> 0 | F15: =M15 -> 10 | G15: =D15-E15-F15 -> 3 | K15: =+G15 -> 3 | L15: =+IPPODROM!J11+IPPODROM!J12+IPPODROM!J13+IPPODROM!J14+IPPODROM!J15+IPPODROM!J16+IPPODROM!J17+IPPODROM!J18+IPPODROM!J19+IPPODROM!J22+IPPODROM!J23+IPPODROM!J20+IPPODROM!J21 -> 0 | M15: =+IPPODROM!M11+IPPODROM!M12+IPPODROM!M13+IPPODROM!M14+IPPODROM!M15+IPPODROM!M16+IPPODROM!M17+IPPODROM!M18+IPPODROM!M19+IPPODROM!M22+IPPODROM!M23+IPPODROM!M20+IPPODROM!M21 -> 10 | N15: =+IPPODROM!N11+IPPODROM!N12+IPPODROM!N13+IPPODROM!N14+IPPODROM!N15+IPPODROM!N16+IPPODROM!N17+IPPODROM!N18+IPPODROM!N19+IPPODROM!N22+IPPODROM!N23+IPPODROM!N20+IPPODROM!N21 -> 13
B16: 7 | C16: СМЕТНЫЙ ОТДЕЛ | D16: =+N16 -> 1 | E16: =L16 -> 0 | F16: =M16 -> 1 | G16: =D16-E16-F16 -> 0 | K16: =+G16 -> 0 | L16: =IPPODROM!J10 -> 0 | M16: =IPPODROM!M10 -> 1 | N16: =IPPODROM!N10 -> 1
B17: 8 | C17: ИНЖЕНЕР ЭЛЕКТРИК / ELECTRICAL CHIEF | D17: =+N17 -> 4 | E17: =L17 -> 0 | F17: =M17 -> 1 | G17: =D17-E17-F17 -> 3 | K17: =+G17 -> 3 | L17: =+IPPODROM!J24+IPPODROM!J25+IPPODROM!J26+IPPODROM!J27 -> 0 | M17: =+IPPODROM!M24+IPPODROM!M25+IPPODROM!M26+IPPODROM!M27 -> 1 | N17: =+IPPODROM!N24+IPPODROM!N25+IPPODROM!N26+IPPODROM!N27 -> 4
B18: 9 | C18: ИНЖЕНЕР МЕХАНИК / MECHANICAL CHIEF | D18: =+N18 -> 1 | E18: =L18 -> 0 | F18: =M18 -> 0 | G18: =D18-E18-F18 -> 1 | K18: =+G18 -> 1 | L18: =+IPPODROM!J28 -> 0 | M18: =+IPPODROM!M28 -> 0 | N18: =+IPPODROM!N28 -> 1
B19: 10 | C19: ИНЖЕНЕР ПТО / DESIGN TECH.ENGINEER | D19: =+N19 -> 5 | E19: =L19 -> 1 | F19: =M19 -> 0 | G19: =D19-E19-F19 -> 4 | K19: =+G19 -> 4 | L19: =IPPODROM!J29+IPPODROM!J30+IPPODROM!J31+IPPODROM!J32+IPPODROM!J33 -> 1 | M19: =IPPODROM!M29+IPPODROM!M30+IPPODROM!M31+IPPODROM!M32+IPPODROM!M33 -> 0 | N19: =IPPODROM!N29+IPPODROM!N30+IPPODROM!N31+IPPODROM!N32+IPPODROM!N33 -> 5
B20: 11 | C20: ОТДЕЛ КАДРОВ / СЕКРЕТЕРЬ/ - PERSONNEL, SEKRETARY, | D20: =+N20 -> 0 | E20: =L20 -> 0 | F20: =M20 -> 0 | G20: =D20-E20-F20 -> 0 | K20: =+G20 -> 0
B21: 12 | C21: ОТДЕЛ СНАБЖЕНИЯ | D21: =+N21 -> 2 | E21: =L21 -> 0 | F21: =M21 -> 0 | G21: =D21-E21-F21 -> 2 | K21: =+G21 -> 2 | L21: =+IPPODROM!J36 -> 0 | M21: =+IPPODROM!M36+IPPODROM!M35 -> 0 | N21: =+IPPODROM!N36+IPPODROM!N35 -> 2
B22: 13 | C22: БУХГАЛТЕР / ACCOUNTING | D22: =+N22 -> 1 | E22: =L22 -> 0 | F22: =M22 -> 0 | G22: =D22-E22-F22 -> 1 | K22: =+G22 -> 1 | L22: =+IPPODROM!J34+IPPODROM!J35 -> 0 | M22: =+IPPODROM!M34 -> 0 | N22: =+IPPODROM!N34 -> 1
B23: 14 | C23: ДОКТОР | D23: =+N23 -> 0 | E23: =L23 -> 0 | F23: =M23 -> 0 | G23: =D23-E23-F23 -> 0 | K23: =+G23 -> 0
B24: 15 | C24: ГЕОДЕЗИСТ / TOPOGRAPHER+Asst | D24: ='GUNLUK RAPOR'!D8 -> 1 | E24: ='GUNLUK RAPOR'!I8 -> 0 | F24: ='GUNLUK RAPOR'!J8 -> 0 | G24: =D24-E24-F24 -> 1 | K24: =SUM(K10:K23) -> 20 | L24: =SUM(L10:L23) -> 1 | M24: =SUM(M10:M23) -> 13 | N24: =SUM(N10:N23) -> 34
B25: 16 | C25: КЛАДОВЩИК | D25: =+'GUNLUK RAPOR'!D9 -> 1 | E25: ='GUNLUK RAPOR'!I9 -> 0 | F25: ='GUNLUK RAPOR'!J9 -> 0 | G25: =D25-E25-F25 -> 1
C26: UNPRODUCTIVE LABOUR | D26: =SUM(D10:D25) -> 36 | E26: =SUM(E10:E25) -> 1 | F26: =SUM(F10:F25) -> 13 | G26: =SUM(G10:G25) -> 22
C27: TOTAL PERSONNEL | D27: =+D8+D26 -> 39 | E27: =+E8+E26 -> 2 | F27: =+F8+F26 -> 14 | G27: =+G8+G26 -> 23
C28: SUBCONT. PRODUCTIVE PERSONNEL LIST | D28: General Staff | E28: Out of Working Staff | F28: Leave / Holiday / Sick | G28: TOTAL
B29: 1 | C29: =+'GUNLUK RAPOR'!B13 -> ИП КУЗНЕЦОВА | D29: ='GUNLUK RAPOR'!D13 -> 9 | E29: ='GUNLUK RAPOR'!I13 -> 0 | F29: ='GUNLUK RAPOR'!J13 -> 0 | G29: =+D29-E29 -> 9
B30: 2 | C30: =+'GUNLUK RAPOR'!B14 -> ИП"ЖЕЛУДЫ.А.А" | D30: ='GUNLUK RAPOR'!D14 -> 13 | E30: ='GUNLUK RAPOR'!I14 -> 0 | F30: ='GUNLUK RAPOR'!J14 -> 0 | G30: =+D30-E30 -> 13
B31: 3 | C31: =+'GUNLUK RAPOR'!B15 -> СПЕЦСТРОЙПРОЕКТ | D31: ='GUNLUK RAPOR'!D15 -> 46 | E31: ='GUNLUK RAPOR'!I15 -> 0 | F31: ='GUNLUK RAPOR'!J15 -> 0 | G31: =+D31-E31 -> 46
B32: 4 | C32: =+'GUNLUK RAPOR'!B16 -> ПАМП ГРУПП | D32: ='GUNLUK RAPOR'!D16 -> 40 | E32: ='GUNLUK RAPOR'!I16 -> 0 | F32: ='GUNLUK RAPOR'!J16 -> 0 | G32: =+D32-E32 -> 40
B33: 5 | C33: =+'GUNLUK RAPOR'!B17 -> ООО ВОЗРОЖДЕНИЕ | D33: ='GUNLUK RAPOR'!D17 -> 22 | E33: ='GUNLUK RAPOR'!I17 -> 0 | F33: ='GUNLUK RAPOR'!J17 -> 0 | G33: =+D33-E33 -> 22
B34: 6 | C34: =+'GUNLUK RAPOR'!B18 -> ООО АДЕЛЬ ТЕХНОЛОДЖИ | D34: ='GUNLUK RAPOR'!D18 -> 2 | E34: ='GUNLUK RAPOR'!I18 -> 0 | F34: ='GUNLUK RAPOR'!J18 -> 0 | G34: =+D34-E34 -> 2
B35: 8 | C35: =+'GUNLUK RAPOR'!B19 -> ИП КАЙТУЕВ | D35: ='GUNLUK RAPOR'!D19 -> 13 | E35: ='GUNLUK RAPOR'!I19 -> 0 | F35: ='GUNLUK RAPOR'!J19 -> 0 | G35: =+D35-E35 -> 13
B36: 9 | C36: =+'GUNLUK RAPOR'!B20 -> ООО"МЦПиС" | D36: ='GUNLUK RAPOR'!D20 -> 68 | E36: ='GUNLUK RAPOR'!I20 -> 0 | F36: ='GUNLUK RAPOR'!J20 -> 0 | G36: =+D36-E36 -> 68
B37: 10 | C37: =+'GUNLUK RAPOR'!B21 -> ООО"СК ПЕГАС" | D37: ='GUNLUK RAPOR'!D21 -> 7 | E37: ='GUNLUK RAPOR'!I21 -> 0 | F37: ='GUNLUK RAPOR'!J21 -> 0 | G37: =+D37-E37 -> 7
B38: 11 | C38: =+'GUNLUK RAPOR'!B22 -> ООО "ХУДОЖЕСТВЕННАЯ РЕСТАВРАЦИЯ" | D38: ='GUNLUK RAPOR'!D22 -> 26 | E38: ='GUNLUK RAPOR'!I22 -> 0 | F38: ='GUNLUK RAPOR'!J22 -> 0 | G38: =+D38-E38 -> 26
B39: 12 | C39: =+'GUNLUK RAPOR'!B23 -> ИП ХЛЕБНИКОВА К.А. | D39: ='GUNLUK RAPOR'!D23 -> 12 | E39: ='GUNLUK RAPOR'!I23 -> 0 | F39: ='GUNLUK RAPOR'!J23 -> 0 | G39: =+D39-E39 -> 12
C40: TOTAL SUBCONTRACTOR | D40: =SUM(D29:D39) -> 258 | E40: =SUM(E29:E39) -> 0 | F40: =SUM(F29:F39) -> 0 | G40: =SUM(G29:G39) -> 258
C41: GRAND TOTAL PERSONNEL | D41: =D40+D27 -> 297 | E41: =E40+E27 -> 2 | F41: =F40+F27 -> 14 | G41: =G40+G27 -> 281
...

Sheet IPPODROM
A1: Монарт-Ипподром Монарт | I1: =+CHOOSE(WEEKDAY(I2,2),"Понедельник","Вторник","Среда","Четверг","Пятница","Суббота","Воскресенье.") -> Суббота | J1: yok | K1: gunduz | L1: geca | M1: dis | N1: sayi
A2: NO | B2: КОД | C2: Ofis Personel / Итр | D2: ФИО / isim soyad | E2: Професий / meslek | F2: NM | G2: FM | H2: Общий | I2: 46123
A3: 1 | B3: 9001 | C3: Nikita Prikazchikov | D3: Приказчиков Никита Алексеевич | E3: PROJE MUDURU YARDIMCISI | F3: X | K3: 1 | N3: 1
A4: 2 | B4: 9003 | C4: Almaz Mukhundinov | D4: Мухутдинов Алмаз Ильясович | E4: PROJE MUDURU YARDIMCISI | F4: X | K4: 1 | N4: 1
A5: 3 | B5: 9011 | C5: Anastasia Shkola | D5: Школа Анастасия Андреевна | E5: BAS MIMAR | F5: X | K5: 1 | N5: 1
A6: 4 | B6: 9004 | C6: Natalya Podmareva | D6: Подмарева Наталья Викторовна | E6: BAS MIMAR | F6: X | K6: 1 | N6: 1
A7: 5 | B7: 9015 | C7: Valentina Miroshkina | D7: Мирошкина Валентина Петровна | E7: BAS MIMAR | F7: X | K7: 1 | N7: 1
A8: 6 | B8: 9002 | C8: Bernikov Ilya Sergeevic | D8: Берников Илья Сергеевич | E8: SANTIYE SEFI | F8: X | K8: 1 | N8: 1
A9: 7 | B9: 9010 | C9: Artom Gurin | D9: Гурин Артем Викторович | E9: SANTIYE SEFI | F9: 0 | I9: DIS GOREV NIZHNY NOVGOROD | K9: 0 | M9: 1 | N9: 1
A10: 8 | B10: 9020 | C10: Irina Portnova | D10: Портнова Ирина Владимировна | E10: SMETA MUHENDISI | F10: X | I10: UZAKTAN CALISIYOR | K10: 0 | M10: 1 | N10: 1
A11: 9 | B11: 9025 | C11: Pavel Bigeza | D11: Бигеза Павел Петрович | E11: BAS MUHENDIS | F11: 0 | I11: DIS GOROV MERKEZ OFIS | K11: 0 | M11: 1 | N11: 1
A12: 10 | B12: 9027 | C12: Vitaliy Juravlev | D12: Журавлев Виталий Сергеевич | E12: BAS MUHENDIS | F12: 0 | I12: DIS GOROV MERKEZ OFIS | K12: 0 | M12: 1 | N12: 1
A13: 11 | B13: 9031 | C13: Nikita Samarin | D13: Самарин Никита Сергеевич | E13: BAS MUHENDIS | F13: 0 | I13: DIS GOROV MERKEZ OFIS | K13: 0 | M13: 1 | N13: 1
A14: 12 | B14: 9033 | C14: Dimitriy Yakovlev | D14: Яковлев Дмитрий Николаевич | E14: BAS MUHENDIS | F14: 0 | I14: DIS GOROV MERKEZ OFIS | K14: 0 | M14: 1 | N14: 1
A15: 13 | B15: 9040 | C15: Vasiliy Sopin | D15: Сопин Василий Валерьевич | E15: SAHA MUHENDISI | F15: 0 | I15: DIS GOREV SKOLKOVO | K15: 0 | M15: 1 | N15: 1
A16: 14 | B16: 9009 | C16: Andrey Podmarev | D16: Подмарев Андрей Олегович | E16: INSAAT MUHENDISI | F16: 0 | I16: DIS GOREV ИнтерРАО | K16: 0 | M16: 1 | N16: 1
A17: 15 | B17: 9024 | C17: Artyom Chvanov | D17: Чванов Артем Дмитриевич | E17: INSAAT MUHENDISI | F17: X | K17: 1 | N17: 1
A18: 16 | B18: 9034 | C18: Maxim Sizov | D18: Сизов Максим Александрович | E18: INSAAT MUHENDISI | F18: X | K18: 1 | N18: 1
A19: 17 | B19: 9041 | C19: Denis Steblevsky | D19: Стеблевский Денис Андреевич | E19: INSAAT MUHENDISI | F19: X | K19: 1 | N19: 1
A20: 18 | B20: 9046 | C20: Egor Litvinov | D20: Литвинов Егор Витальевич | E20: MAKINA MUHENDISI | F20: 0 | I20: DIS GOROV MERKEZ OFIS | K20: 0 | M20: 1 | N20: 1
A21: 19 | B21: 9047 | C21: Kirill Cernikov | D21: Черников Кирилл Михайлович | E21: MAKINA MUHENDISI | F21: 0 | I21: DIS GOREV SKOLKOVA | K21: 0 | M21: 1 | N21: 1
A22: 20 | B22: 9029 | C22: Sergey Lejnev | D22: Лежнев Сергей Михайлович | E22: INSAAT DENETLEME | F22: 0 | I22: DIS GOREV SKOLKOVA | K22: 0 | M22: 1 | N22: 1
A23: 21 | B23: 9030 | C23: Ilya Murjikneli | D23: Муржикнели Илья Евгеньевич | E23: INSAAT DENETLEME | F23: 0 | I23: DIS GOREV SKOLKOVA | K23: 0 | M23: 1 | N23: 1
A24: 22 | B24: 9038 | C24: Ilya Korshunov | D24: Коршунов Илья Рифатович | E24: ELEKTRIK P.T.O MUHENDISI | F24: X | K24: 1 | N24: 1
A25: 23 | B25: 9005 | C25: Ekaterina Sharipova | D25: Шарипова Екатерина Зуфаровна | E25: ELEKTRIK P.T.O MUHENDISI | F25: X | K25: 1 | N25: 1
A26: 24 | B26: 9044 | C26: Mehmet Fatih Guven | D26: Гювен Мехмет Фатих | E26: ELEKTRIK MUHENDISI | F26: X | K26: 1 | N26: 1
A27: 25 | B27: 9028 | C27: Artom Kokin | D27: Кокин Артем Георгиевич | E27: KALITE MUHENDISI | F27: 0 | I27: DIS GOROV MERKEZ OFIS | K27: 0 | M27: 1 | N27: 1
A28: 26 | B28: 9014 | C28: Mariya Belgin | D28: Белгин Мария Николаевна | E28: PTO (MEKANIK) MUHENDISI | F28: X | K28: 1 | N28: 1
A29: 27 | B29: 9000 | C29: Natalya Rostmistrova | D29: Ротмистрова Наталия Александровна | E29: P.T.O SEFI | F29: 0 | I29: HASTA | J29: 1 | K29: 0 | N29: 1
A30: 28 | B30: 9013 | C30: Lyudmila Malinina | D30: Малинина Людмила Петровна | E30: P.T.O MUHENDISI | F30: X | K30: 1 | N30: 1
A31: 29 | B31: 9016 | C31: Aleksandr Sevostyanov | D31: Севостьянов Александр Павлович | E31: P.T.O STAJOR | F31: X | K31: 1 | N31: 1
A32: 30 | B32: 9022 | C32: Kirill Pesevenknikov | D32: Пшеничников Кирилл Александрович | E32: P.T.O STAJOR | F32: X | K32: 1 | N32: 1
A33: 31 | B33: 9023 | C33: Aydarbek Yuldasev | D33: Юлдашев Аидарбек Шухратбекович | E33: P.T.O STAJOR | F33: X | K33: 1 | N33: 1
A34: 32 | B34: 9043 | C34: Denis Bezrukov | D34: Безруков Денис Алксандрович | E34: MUHASEBECI | F34: X | K34: 1 | N34: 1
A35: 33 | B35: 9045 | C35: Berkman Berkay Tas | D35: Таш Беркман Беркай | E35: SATINALMA SEFI | F35: X | K35: 1 | N35: 1
A36: 34 | B36: 9008 | C36: Anna Karostina | D36: Каростина Анна Васильевна | E36: SATINALMA | F36: X | K36: 1 | N36: 1
B37: ГЕОДЕЗИСТ /TOPOGRAF TAHA TILEGI | J37: =SUM(J3:J36) -> 1 | K37: =SUM(K3:K36) -> 20 | L37: =SUM(L3:L36) -> 0 | M37: =SUM(M3:M36) -> 13 | N37: =SUM(N3:N36) -> 34
A38: 1 | B38: 9018 | C38: Anton Matseyko | D38: Мацейко Антон Юрьевич | E38: TOPOGRAF | F38: X | K38: 1
B39: DEPO/ КЛАДОВЩИК | J39: =SUM(J38:J38) -> 0 | K39: =SUM(K38:K38) -> 1 | L39: =SUM(L38:L38) -> 0 | M39: =SUM(M38:M38) -> 0
A40: 1 | B40: 9042 | C40: Elyorjon Olamov | D40: Оламов Элёржон Эргашбоевич | E40: AMBAR OPERATORU | F40: Х | K40: 1
...

Sheet Лист2
C3: 4267 | D3: Asrorjon Ergashev | E3: Эргашев Асрорджон Ахматович | F3: INCE ISLER EKIPBASI | G3: Х | J3: SAHA | L3: 1
C4: 4268 | D4: Farkhod Kobilkhujaev | E4: Кобилхуджаев Фарход Рустамович | F4: INCE ISLER EKIPBASI | G4: Х | J4: SAHA | L4: 1
C5: 5134 | D5: Bunyod Dilmurotov | E5: Дилмуротов Бунёд Бобомурод Угли | F5: INCE ISLER EKIPBASI | G5: 0 | J5: DIS GOREV IKB | L5: 0 | N5: 1
C6: 5268 | D6: Mukhammadaziz Kodiraliev | E6: Кодиралиев Мухаммадазиз Сохибжон Угли | F6: INCE ISLER EKIPBASI | G6: 0 | J6: DIS GOREV ИнтерРАО | L6: 0 | N6: 1
C7: 5652 | D7: Kholmirza Meyliev | E7: Мейлиев Холмирза Асадулло Угли | F7: ALCI BOYA USTASI | G7: 7.5 | H7: 2.5 | I7: =IF(H7>0,(H7*1.5)+G7,"YOK") -> 11.25 | J7: TRIBUNA TAVAN SIVA IMALATI | L7: 1
C8: 4278 | D8: Muso Muhabbatov | E8: Мухаббатов Мусо Саъдуллоевич | F8: ALCI BOYA USTASI | G8: 7.5 | H8: 2.5 | I8: =IF(H8>0,(H8*1.5)+G8,"YOK") -> 11.25 | J8: TRIBUNA TAVAN SIVA IMALATI | L8: 1
C9: 5271 | D9: Khalimjon Akhmedov | E9: Ахмедов Халимжон Расулджонович | F9: ALCIPAN USTASI | G9: 7.5 | H9: 2.5 | I9: =IF(H9>0,(H9*1.5)+G9,"YOK") -> 11.25 | J9: TRIBUNA TAVAN SIVA IMALATI | L9: 1
C10: 5047 | D10: Saidburhon Abdulloev | E10: Абдуллоев Саидбурхон Абдурахмонович | F10: DUVAR USTASI | G10: 7.5 | H10: 2.5 | I10: =IF(H10>0,(H10*1.5)+G10,"YOK") -> 11.25 | J10: TRIBUNA TAVAN SIVA IMALATI | L10: 1
C11: 5424 | D11: Umedjon Davlatov | E11: Давлатов Умеджон Хусейнович | F11: DUVAR USTASI | G11: 7.5 | H11: 2.5 | I11: =IF(H11>0,(H11*1.5)+G11,"YOK") -> 11.25 | J11: TRIBUNA TAVAN SIVA IMALATI | L11: 1
C12: 4633 | D12: Hojisalmon Usmonshoev | E12: Усмоншоев Ходжисалмон Хошимджонович | F12: DUVAR USTASI | G12: 7.5 | H12: 2.5 | I12: =IF(H12>0,(H12*1.5)+G12,"YOK") -> 11.25 | J12: ARENA DUVAR SILIM VE BOYASI | L12: 1
C13: 5445 | D13: Dustmurod Gadoev | E13: Гадоев Дустмурод Эмомджонович | F13: DUVAR USTASI | G13: 7.5 | H13: 2.5 | I13: =IF(H13>0,(H13*1.5)+G13,"YOK") -> 11.25 | J13: ARENA DUVAR SILIM VE BOYASI | L13: 1
C14: 4998 | D14: Safarali Rahmonov | E14: Рахмонов Сафарали Махсудбекович | F14: DUVAR USTASI | G14: 7.5 | H14: 2.5 | I14: =IF(H14>0,(H14*1.5)+G14,"YOK") -> 11.25 | J14: ARENA DUVAR SILIM VE BOYASI | L14: 1
C15: 5715 | D15: Samariddin Bobobekov | E15: Бобобеков Самариддин Абилкосим Угли | F15: DUVAR USTASI | G15: 7.5 | H15: 2.5 | I15: =IF(H15>0,(H15*1.5)+G15,"YOK") -> 11.25 | J15: ARENA DUVAR SILIM VE BOYASI | L15: 1
C16: 5713 | D16: Jasur Murodov | E16: Муродов Жасур Ирискулович | F16: DUVAR USTASI | G16: 7.5 | H16: 2.5 | I16: =IF(H16>0,(H16*1.5)+G16,"YOK") -> 11.25 | J16: ARENA DUVAR SILIM VE BOYASI | L16: 1
C17: 5719 | D17: Asadbek Karimov | E17: Каримов Асадбек Давлат Угли | F17: DUVAR USTASI | G17: 7.5 | H17: 2.5 | I17: =IF(H17>0,(H17*1.5)+G17,"YOK") -> 11.25 | J17: ARENA DUVAR SILIM VE BOYASI | L17: 1
C18: 5105 | D18: Nazliddin Muzaffarov | E18: Музаффаров Назриддин Назюллоевич | F18: DUVAR USTASI | G18: 7.5 | H18: 2.5 | I18: =IF(H18>0,(H18*1.5)+G18,"YOK") -> 11.25 | J18: 1 KAT SOKUL DUVAR IMALATI | L18: 1
C19: 4638 | D19: Shahzod Murodullaev | E19: Муродуллаев Шахзод Акмал Угли | F19: DUVAR USTASI | G19: 7.5 | H19: 2.5 | I19: =IF(H19>0,(H19*1.5)+G19,"YOK") -> 11.25 | J19: 1 KAT SOKUL DUVAR IMALATI | L19: 1
C20: 4635 | D20: Abubakr Fayziddinov | E20: Файзиддинов Абубакр Садирович | F20: DUVAR USTASI | G20: 0 | H20: 0 | I20: =IF(H20>0,(H20*1.5)+G20,"YOK") -> YOK | J20: ISE CIKMADI | K20: 1 | L20: 0
C21: 5714 | D21: Asliddin Arifjanov | E21: Арифжанов Аслиддин Дувланович | F21: DUVAR USTASI | G21: 0 | H21: 0 | I21: =IF(H21>0,(H21*1.5)+G21,"YOK") -> YOK | J21: ISE CIKMADI | K21: 1 | L21: 0
C22: 4687 | D22: Mustafo Rakhmonov | E22: Рахмонов Мустафо Сафаралиевич | F22: SAPCI | G22: 7.5 | H22: 2.5 | I22: =IF(H22>0,(H22*1.5)+G22,"YOK") -> 11.25 | J22: ARENA DUVAR SILIM VE BOYASI | L22: 1
C23: 5270 | D23: Ummatali Mavlonov | E23: Мавлонов Умматали Рахманалиевич | F23: SERAMIK USTASI | G23: 7.5 | H23: 2.5 | I23: =IF(H23>0,(H23*1.5)+G23,"YOK") -> 11.25 | J23: FASAD BETON VE DUVAR DEMONTAC | L23: 1
C24: 4475 | D24: Ibrokhimdjon Saiburkhonov | E24: Сайбурхонов Иброхимджон Солехович | F24: SERAMIK USTASI | G24: 7.5 | H24: 2.5 | I24: =IF(H24>0,(H24*1.5)+G24,"YOK") -> 11.25 | J24: FASAD BETON VE DUVAR DEMONTAC | L24: 1
C25: 4601 | D25: Adilbek Khalmuratov | E25: Халмуратов Адилбек Аширбаевич | F25: SERAMIK USTASI | G25: 7.5 | H25: 2.5 | I25: =IF(H25>0,(H25*1.5)+G25,"YOK") -> 11.25 | J25: ATAPLENI YERLAR SIVA IMALATI | L25: 1
C26: 5570 | D26: Ruzimbay Djumashev | E26: Джумашев Рузимбай Султанович | F26: SERAMIK USTASI | G26: 7.5 | H26: 2.5 | I26: =IF(H26>0,(H26*1.5)+G26,"YOK") -> 11.25 | J26: ARENA DUVAR SILIM VE BOYASI | L26: 1
C27: 4374 | D27: Farkhod Allabergenov | E27: Аллабергенов Фархад Розибаевич | F27: SERAMIK USTASI | G27: 7.5 | H27: 2.5 | I27: =IF(H27>0,(H27*1.5)+G27,"YOK") -> 11.25 | J27: ARENA DUVAR SILIM VE BOYASI | L27: 1
C28: 4400 | D28: Suhrob Kobilhujaev | E28: Кобилхуджаев Сухроб Рустамович | F28: SERAMIK USTASI | G28: 7.5 | H28: 2.5 | I28: =IF(H28>0,(H28*1.5)+G28,"YOK") -> 11.25 | J28: ARENA DUVAR SILIM VE BOYASI | L28: 1
C29: DG | D29: Hojivali Badiev | E29: Бадиев Ходживали Давлатбекович | F29: SERAMIK USTASI | G29: 7.5 | H29: 2.5 | I29: =IF(H29>0,(H29*1.5)+G29,"YOK") -> 11.25 | J29: DIS GOREV ИнтерРАОDEN GELDI | L29: 1
C30: 5242 | D30: Pardali Sherkhonov | E30: Шерхонов Пардали Давлатович | F30: SIVACI | G30: 7.5 | H30: 2.5 | I30: =IF(H30>0,(H30*1.5)+G30,"YOK") -> 11.25 | J30: FASAD BETON VE DUVAR DEMONTAC | L30: 1
C31: 5451 | D31: Khursand Matyokubov | E31: Матёкубов Хурсанд Кодирович | F31: SIVACI | G31: 7.5 | H31: 2.5 | I31: =IF(H31>0,(H31*1.5)+G31,"YOK") -> 11.25 | J31: FASAD BETON VE DUVAR DEMONTAC | L31: 1
C32: 5454 | D32: Murodbek Madrimov | E32: Мадримов Муродбек Комилжонович | F32: SIVACI | G32: 7.5 | H32: 2.5 | I32: =IF(H32>0,(H32*1.5)+G32,"YOK") -> 11.25 | J32: FASAD BETON VE DUVAR DEMONTAC | L32: 1
C33: 5577 | D33: Amirbek Safarov | E33: Сафаров Амирбек Абдумуталибович | F33: SIVACI | G33: 7.5 | H33: 2.5 | I33: =IF(H33>0,(H33*1.5)+G33,"YOK") -> 11.25 | J33: FASAD BETON VE DUVAR DEMONTAC | L33: 1
C34: 5378 | D34: Anvar Muminov | E34: Муминов Анвар Азимович | F34: SIVACI | G34: 7.5 | H34: 2.5 | I34: =IF(H34>0,(H34*1.5)+G34,"YOK") -> 11.25 | J34: FASAD BETON VE DUVAR DEMONTAC | L34: 1
C35: 5272 | D35: Azizbek Nabijonov | E35: Набижонов Азизбек Хурсандали Угли | F35: SIVACI | G35: 7.5 | H35: 2.5 | I35: =IF(H35>0,(H35*1.5)+G35,"YOK") -> 11.25 | J35: FASAD BETON VE DUVAR DEMONTAC | L35: 1
C36: 5198 | D36: Samariddin Safarov | E36: Сафаров Самариддин Сафаралиевич | F36: SIVACI | G36: 7.5 | H36: 2.5 | I36: =IF(H36>0,(H36*1.5)+G36,"YOK") -> 11.25 | J36: FASAD BETON VE DUVAR DEMONTAC | L36: 1
C37: 5200 | D37: Saydali Holboboev | E37: Холбобоев Сайдали Тайлонович | F37: SIVACI | G37: 7.5 | H37: 2.5 | I37: =IF(H37>0,(H37*1.5)+G37,"YOK") -> 11.25 | J37: FASAD BETON VE DUVAR DEMONTAC | L37: 1
C38: 5237 | D38: Nekruz Holmadzoda | E38: Холмадзода Некруз Хасан | F38: SIVACI | G38: 7.5 | H38: 2.5 | I38: =IF(H38>0,(H38*1.5)+G38,"YOK") -> 11.25 | J38: FASAD BETON VE DUVAR DEMONTAC | L38: 1
C39: 4723 | D39: Elmurod Ortikov | E39: Ортиков Элмурод Камолбек Угли | F39: SIVACI | G39: 7.5 | H39: 2.5 | I39: =IF(H39>0,(H39*1.5)+G39,"YOK") -> 11.25 | J39: FASAD BETON VE DUVAR DEMONTAC | L39: 1
C40: 5716 | D40: Khudoyberdi Ortikov | E40: Ортиков Худайбекрди Абдишукурович | F40: SIVACI | G40: 0 | H40: 0 | I40: =IF(H40>0,(H40*1.5)+G40,"YOK") -> YOK | J40: ISE CIKMADI | K40: 1 | L40: 0
C41: 4634 | D41: Sirojidin Gafurov | E41: Гафуров Сирожидин Гиёсидинович | F41: SIVACI USTASI | G41: 7.5 | H41: 2.5 | I41: =IF(H41>0,(H41*1.5)+G41,"YOK") -> 11.25 | J41: FASAD BETON VE DUVAR DEMONTAC | L41: 1
C42: 4637 | D42: Avrosul Usmonshoev | E42: Усмоншоев Авросул Хошимович | F42: SIVACI USTASI | G42: 7.5 | H42: 2.5 | I42: =IF(H42>0,(H42*1.5)+G42,"YOK") -> 11.25 | J42: ATAPLENI YERLAR SIVA IMALATI | L42: 1
...

Sheet GUNLUK RAPOR
B1: Монарт Ипподром | I1: =+IPPODROM!I2 -> 46123 | J1: =+IPPODROM!I1 -> Суббота
B2: EKIP | C2: EKIP SORUMLUSU | D2: TOPLAM MAVCUT | E2: TOPLAM CALISAN | F2: GUNDUZ CALISAN | G2: GECE CALISAN | H2: TOPLAM GELMEYEN | I2: SANTIYEYE GELMEYEN | J2: DIS GOREV
B3: IS GUVENLIK EKIBI | C3: ALEKSEY ANTIPOV | D3: =+IPPODROM!A43 -> 2 | E3: =IPPODROM!K44 -> 1 | F3: =E3-G3 -> 1 | G3: =IPPODROM!L44 -> 0 | H3: =D3-E3 -> 1 | I3: =IPPODROM!J42 -> 1 | J3: =IPPODROM!M44 -> 0
B4: INCE ISLER-AKBARALI | C4: AKBARALI | D4: =+IPPODROM!A45 -> 1 | E4: =+IPPODROM!K46 -> 0 | F4: =E4-G4 -> 0 | G4: =IPPODROM!L45 -> 0 | H4: =D4-E4 -> 1 | I4: =IPPODROM!J45 -> 0 | J4: =+IPPODROM!M46 -> 1
B5: DIREK TOPLAM | D5: =SUM(D3:D4) -> 3 | E5: =SUM(E3:E4) -> 1 | F5: =SUM(F3:F4) -> 1 | G5: =SUM(G3:G4) -> 0 | H5: =SUM(H3:H4) -> 2 | I5: =SUM(I3:I4) -> 1 | J5: =SUM(J3:J4) -> 1
B6: ENDIREK VE HIZMETLI
B7: TEKNIK IDARE | D7: =IPPODROM!N37 -> 34 | E7: =IPPODROM!K37 -> 20 | F7: =E7-G7 -> 20 | G7: =IPPODROM!L37 -> 0 | H7: =D7-E7 -> 14 | I7: =IPPODROM!J37 -> 1 | J7: =IPPODROM!M37 -> 13
B8: TOPOGRAF | D8: =+IPPODROM!A38 -> 1 | E8: =IPPODROM!K39 -> 1 | F8: =E8-G8 -> 1 | G8: =IPPODROM!L39 -> 0 | H8: =D8-E8 -> 0 | I8: =IPPODROM!J39 -> 0 | J8: =IPPODROM!M39 -> 0
B9: AMBARCI | D9: =+IPPODROM!A40 -> 1 | E9: =IPPODROM!K40 -> 1 | F9: =E9-G9 -> 1 | G9: =+IPPODROM!L46 -> 0 | H9: =D9-E9 -> 0 | I9: =+IPPODROM!J41 -> 0 | J9: =+IPPODROM!M41 -> 0
B10: ENDIREK TOPLAM | D10: =SUM(D7:D9) -> 36 | E10: =SUM(E7:E9) -> 22 | F10: =SUM(F7:F9) -> 22 | G10: =SUM(G7:G9) -> 0 | H10: =SUM(H7:H9) -> 14 | I10: =SUM(I7:I9) -> 1 | J10: =SUM(J7:J9) -> 13
B11: Монарт Ипподром TOPLAM | D11: =+D10+D5 -> 39 | E11: =+E10+E5 -> 23 | F11: =+F10+F5 -> 23 | G11: =+G10+G5 -> 0 | H11: =+H10+H5 -> 16 | I11: =+I10+I5 -> 2 | J11: =+J10+J5 -> 14
B13: ИП КУЗНЕЦОВА | C13: 7909-518-58-36 | D13: 9 | E13: =D13 -> 9 | F13: =E13-G13 -> 9
B14: ИП"ЖЕЛУДЫ.А.А" | C14: 7919-772-74-80 | D14: 13 | E14: =D14 -> 13 | F14: =E14-G14 -> 13
B15: СПЕЦСТРОЙПРОЕКТ | C15: 7925-847-15-57 | D15: 46 | E15: =D15 -> 46 | F15: =E15-G15 -> 46 | G15: 0 | H15: =D15-E15 -> 0
B16: ПАМП ГРУПП | C16: 7989-727-22-68 | D16: 40 | E16: =D16 -> 40 | F16: =E16-G16 -> 40 | G16: 0 | H16: =D16-E16 -> 0
B17: ООО ВОЗРОЖДЕНИЕ | C17: 7926-527-13-88 | D17: 22 | E17: =D17 -> 22 | F17: =E17-G17 -> 22 | G17: 0 | H17: =D17-E17 -> 0
B18: ООО АДЕЛЬ ТЕХНОЛОДЖИ | C18: 7925-224-60-50 | D18: 2 | E18: =D18 -> 2 | F18: =E18-G18 -> 2 | G18: 0 | H18: =D18-E18 -> 0
B19: ИП КАЙТУЕВ | C19: 7903-643-84-94 | D19: 13 | E19: =D19 -> 13 | F19: =E19-G19 -> 13 | G19: 0 | H19: =D19-E19 -> 0
B20: ООО"МЦПиС" | C20: 7963-769-24-15 | D20: 68 | E20: =D20 -> 68 | F20: =E20-G20 -> 68 | G20: 0 | H20: =D20-E20 -> 0
B21: ООО"СК ПЕГАС" | C21: 7985-813-85-91 | D21: 7 | E21: =D21 -> 7 | F21: =E21-G21 -> 7 | G21: 0 | H21: =D21-E21 -> 0
B22: ООО "ХУДОЖЕСТВЕННАЯ РЕСТАВРАЦИЯ" | C22: 7968-532-60-93 | D22: 26 | E22: =D22 -> 26 | F22: =E22-G22 -> 26 | G22: 0 | H22: =D22-E22 -> 0
B23: ИП ХЛЕБНИКОВА К.А. | C23: 7926-787-97-57 | D23: 12 | E23: =D23 -> 12 | F23: =E23-G23 -> 12 | G23: 0 | H23: =D23-E23 -> 0
B24: TASERON TOPLAM | D24: =SUM(D13:D23) -> 258 | E24: =SUM(E13:E23) -> 258 | F24: =SUM(F13:F23) -> 258 | G24: =SUM(G13:G23) -> 0 | H24: =SUM(H13:H23) -> 0 | I24: =SUM(I13:I23) -> 0 | J24: =SUM(J13:J23) -> 0
B26: GENEL TOPLAM | D26: =+D24+D11 -> 297 | E26: =+E24+E11 -> 281 | F26: =+F24+F11 -> 281 | G26: =+G24+G11 -> 0 | H26: =+H24+H11 -> 16 | I26: =+I24+I11 -> 2 | J26: =+J24+J11 -> 14
B28: Руководитель Проекта
B29: Селчук Самет
