Workbook

Sheet Meslek Sayi
A1: № | B1: Професий / meslek | C1: Кол-во / sayi | D1: Total | E1: =+C80 -> 987
A2: 1 | B2: ALCI BOYA USTASI | C2: =COUNTIF(IPPODROM!E:E,'Meslek Sayi'!B:B) -> 43
A3: 2 | B3: ALCIPAN USTASI | C3: =COUNTIF(IPPODROM!E:E,'Meslek Sayi'!B:B) -> 59
A4: 3 | B4: ALET OPERATORU | C4: =COUNTIF(IPPODROM!E:E,'Meslek Sayi'!B:B) -> 6
A5: 4 | B5: AMBAR SEFI | C5: =COUNTIF(IPPODROM!E:E,'Meslek Sayi'!B:B) -> 1
A6: 5 | B6: AMBARCI | C6: =COUNTIF(IPPODROM!E:E,'Meslek Sayi'!B:B) -> 16
A7: 6 | B7: BAS MIMAR | C7: =COUNTIF(IPPODROM!E:E,'Meslek Sayi'!B:B) -> 1
A8: 7 | B8: BAS MUHASEBECI | C8: =COUNTIF(IPPODROM!E:E,'Meslek Sayi'!B:B) -> 0
A9: 8 | B9: BAS MUHENDIS MEKANIK | C9: =COUNTIF(IPPODROM!E:E,'Meslek Sayi'!B:B) -> 0
A10: 9 | B10: BEKCI | C10: =COUNTIF(IPPODROM!E:E,'Meslek Sayi'!B:B) -> 20
A11: 10 | B11: BEKCI SORUMLUSU | C11: =COUNTIF(IPPODROM!E:E,'Meslek Sayi'!B:B) -> 3
A12: 11 | B12: BETONCU | C12: =COUNTIF(IPPODROM!E:E,'Meslek Sayi'!B:B) -> 4
A13: 12 | B13: BOLUM BASKANI | C13: =COUNTIF(IPPODROM!E:E,'Meslek Sayi'!B:B) -> 0
... A79: 78 | B79: SAPCI | C79: =COUNTIF(IPPODROM!E:E,'Meslek Sayi'!B:B) -> 1
A80: TOPLAM SAYI | C80: =SUM(C2:C79) -> 987

Sheet Cover page 
B2: Монотекстрой / ИППОДРОМ | H2: =+IPPODROM!I1 -> Пятница
H3: =+IPPODROM!I2 -> 46122
B4: № | C4: Персонал / Personnel | D4: Общий Кадров | E4: НЕ ВЫШЛИ НА РАБОТУ | F4: Бальничный ОТПУСК / Командировка | G4: ОБЩЕЕ
B5: A | C5: РАБОЧИЕ / PRODUCTIVE PERSONEL LIST | D5: General Staff | E5: Out of Working Staff | F5: Leave / Holiday / Sick | G5: TOTAL
B6: 1 | C6: ТЕХНИКА БЕЗОПАСНОСТИ / GUVENLIK | D6: ='GUNLUK RAPOR'!D3 -> 19 | E6: ='GUNLUK RAPOR'!I3 -> 4 | F6: ='GUNLUK RAPOR'!J3 -> 1 | G6: =D6-E6-F6 -> 14
B7: 2 | C7: ЭЛЕКТРИК / ELECTRICIAN | D7: ='GUNLUK RAPOR'!D4 -> 215 | E7: ='GUNLUK RAPOR'!I4 -> 19 | F7: ='GUNLUK RAPOR'!J4 -> 16 | G7: =D7-E7-F7 -> 180
B8: 3 | C8: MEKANIK \ SANTEKNIK-САНТЕХНИК | D8: ='GUNLUK RAPOR'!D5 -> 79 | E8: ='GUNLUK RAPOR'!I5 -> 5 | F8: ='GUNLUK RAPOR'!J5 -> 4 | G8: =D8-E8-F8 -> 70
B9: 4 | C9: MEKANIK \ HAVALANDIRMA | D9: ='GUNLUK RAPOR'!D6 -> 64 | E9: ='GUNLUK RAPOR'!I6 -> 4 | F9: ='GUNLUK RAPOR'!J6 -> 20 | G9: =D9-E9-F9 -> 40
B10: 5 | C10: INCE ISLER BOGIBEK FATKULLIN | D10: ='GUNLUK RAPOR'!D7 -> 124 | E10: ='GUNLUK RAPOR'!I7 -> 6 | F10: ='GUNLUK RAPOR'!J7 -> 12 | G10: =D10-E10-F10 -> 106
B11: 6 | C11: INCE ISLER ASRORJON ERGASHEV | D11: ='GUNLUK RAPOR'!D8 -> 47 | E11: ='GUNLUK RAPOR'!I8 -> 5 | F11: ='GUNLUK RAPOR'!J8 -> 21 | G11: =D11-E11-F11 -> 21
B12: 7 | C12: INCE ISLER ALISHER KADIROV | D12: ='GUNLUK RAPOR'!D9 -> 7 | E12: ='GUNLUK RAPOR'!I9 -> 0 | F12: ='GUNLUK RAPOR'!J9 -> 7 | G12: =D12-E12-F12 -> 0
B13: 8 | C13: INCE ISLER ABROR BERDIBAEV | D13: ='GUNLUK RAPOR'!D10 -> 50 | E13: ='GUNLUK RAPOR'!I10 -> 7 | F13: ='GUNLUK RAPOR'!J10 -> 0 | G13: =D13-E13-F13 -> 43
B14: 9 | C14: INCE ISLER FERUZBEK KULLIEV | D14: ='GUNLUK RAPOR'!D11 -> 120 | E14: ='GUNLUK RAPOR'!I11 -> 6 | F14: ='GUNLUK RAPOR'!J11 -> 6 | G14: =D14-E14-F14 -> 108
B15: 10 | C15: INCE ISLER-AKBARALI | D15: ='GUNLUK RAPOR'!D12 -> 30 | E15: ='GUNLUK RAPOR'!I12 -> 4 | F15: ='GUNLUK RAPOR'!J12 -> 0 | G15: =D15-E15-F15 -> 26
B16: 11 | C16: INCE ISLER YUNUS TUNE | D16: ='GUNLUK RAPOR'!D13 -> 81 | E16: ='GUNLUK RAPOR'!I13 -> 10 | F16: ='GUNLUK RAPOR'!J13 -> 1 | G16: =D16-E16-F16 -> 70
B17: 12 | C17: INCE ISLER SUAT KURNAZ | D17: ='GUNLUK RAPOR'!D14 -> 18 | E17: ='GUNLUK RAPOR'!I14 -> 1 | F17: ='GUNLUK RAPOR'!J14 -> 0 | G17: =D17-E17-F17 -> 17
B18: 13 | C18: =+'GUNLUK RAPOR'!B15 -> INCE ISLER ISMOIL KHUDOYBERGANOV | D18: ='GUNLUK RAPOR'!D15 -> 52 | E18: ='GUNLUK RAPOR'!I15 -> 7 | F18: ='GUNLUK RAPOR'!J15 -> 0 | G18: =D18-E18-F18 -> 45
B19: 14 | C19: =+'GUNLUK RAPOR'!B16 -> INCE ISLER RUSLAN RUZMETOV | D19: ='GUNLUK RAPOR'!D16 -> 10 | E19: ='GUNLUK RAPOR'!I16 -> 0 | F19: ='GUNLUK RAPOR'!J16 -> 0 | G19: =D19-E19-F19 -> 10
B20: 15 | C20: =+'GUNLUK RAPOR'!B17 -> INCE ISLER SARDOR KOCHKAROV | D20: ='GUNLUK RAPOR'!D17 -> 47 | E20: ='GUNLUK RAPOR'!I17 -> 4 | F20: ='GUNLUK RAPOR'!J17 -> 0 | G20: =D20-E20-F20 -> 43
B21: 16 | C21: CEPHECI EKIBI DJAMOLIDDIN ABDIEV | D21: ='GUNLUK RAPOR'!D18 -> 49 | E21: ='GUNLUK RAPOR'!I18 -> 0 | F21: ='GUNLUK RAPOR'!J18 -> 5 | G21: =D21-E21-F21 -> 44
B22: 17 | C22: ПОДСОБНЫЙ РАБОЧИЙ / WORKER / BILAL KELLECI | D22: ='GUNLUK RAPOR'!D19 -> 42 | E22: ='GUNLUK RAPOR'!I19 -> 0 | F22: ='GUNLUK RAPOR'!J19 -> 0 | G22: =D22-E22-F22 -> 42
B23: 18 | C23: ПОДСОБНЫЙ РАБОЧИЙ / WORKER / KENAN KURT | D23: ='GUNLUK RAPOR'!D20 -> 26 | E23: ='GUNLUK RAPOR'!I20 -> 2 | F23: ='GUNLUK RAPOR'!J20 -> 0 | G23: =D23-E23-F23 -> 24
B24: 19 | C24: ПОДСОБНЫЙ РАБОЧИЙ / WORKER / MAKSUD ISMAYLOV | D24: ='GUNLUK RAPOR'!D21 -> 44 | E24: ='GUNLUK RAPOR'!I21 -> 1 | F24: ='GUNLUK RAPOR'!J21 -> 0 | G24: =D24-E24-F24 -> 43
B25: 20 | C25: ПОДСОБНЫЙ РАБОЧИЙ / WORKER / ILHAN KOR | D25: ='GUNLUK RAPOR'!D22 -> 43 | E25: ='GUNLUK RAPOR'!I22 -> 2 | F25: ='GUNLUK RAPOR'!J22 -> 0 | G25: =D25-E25-F25 -> 41
B26: 21 | C26: ПОДСОБНЫЙ РАБОЧИЙ / WORKER / KAKHRAMON KURAMBAEV | D26: ='GUNLUK RAPOR'!D23 -> 28 | E26: ='GUNLUK RAPOR'!I23 -> 1 | F26: ='GUNLUK RAPOR'!J23 -> 0 | G26: =D26-E26-F26 -> 27
B27: 22 | C27: KALIPCI-ОПАЛУБЩИК SAVAS YILMAZ | D27: ='GUNLUK RAPOR'!D24 -> 57 | E27: ='GUNLUK RAPOR'!I24 -> 5 | F27: ='GUNLUK RAPOR'!J24 -> 0 | G27: =D27-E27-F27 -> 52
B28: 23 | C28: KALIPCI-ОПАЛУБЩИК HARUN AKDENIZ | D28: ='GUNLUK RAPOR'!D25 -> 204 | E28: ='GUNLUK RAPOR'!I25 -> 8 | F28: ='GUNLUK RAPOR'!J25 -> 18 | G28: =D28-E28-F28 -> 178
C29: PRODUCTIVE LABOUR | D29: =SUM(D6:D28) -> 1456 | E29: =SUM(E6:E28) -> 101 | F29: =SUM(F6:F28) -> 111 | G29: =SUM(G6:G28) -> 1244 | K29: Santiyede Calisan | L29: Yok ve Izin | M29: Dis Gorev | N29: Toplam
B30: B | C30: ИТР / UNPRODUCTIVE PERSONEL LIST | D30: General Staff | E30: Out of Working Staff | F30: Leave / Holiday / Sick | G30: TOTAL
B31: 1 | C31: РУКОВОДИТЕЛЬ ПРОЕКТА / PROJECT MANAGER | D31: =+N31 -> 3 | E31: =L31 -> 0 | F31: =M31 -> 0 | G31: =D31-E31-F31 -> 3 | K31: =+G31 -> 3 | L31: =+IPPODROM!J3+IPPODROM!J4+IPPODROM!J5 -> 0 | M31: =+IPPODROM!M3+IPPODROM!M4+IPPODROM!M5 -> 0 | N31: =+IPPODROM!N3+IPPODROM!N4+IPPODROM!N5 -> 3
B32: 2 | C32: ЗАМЕСТИТЕЛЬ РУКОВОДИТЕЛЯ ПРОЕКТА / ASS PROJECT MANAGER | D32: =+N32 -> 0 | E32: =L32 -> 0 | F32: =M32 -> 0 | G32: =D32-E32-F32 -> 0 | K32: =+G32 -> 0
B33: 3 | C33: НАЧАЛЬНИК УЧАСТКА / SITE MANAGER | D33: =+N33 -> 1 | E33: =L33 -> 0 | F33: =M33 -> 1 | G33: =D33-E33-F33 -> 0 | K33: =+G33 -> 0 | L33: =+IPPODROM!J6 -> 0 | M33: =+IPPODROM!M6 -> 1 | N33: =+IPPODROM!N6 -> 1
B34: 4 | C34: НАЧАЛЬНИК ТЕХОФИСА /TEKNIK OFIS | D34: =+N34 -> 2 | E34: =L34 -> 0 | F34: =M34 -> 0 | G34: =D34-E34-F34 -> 2 | K34: =+G34 -> 2 | L34: =+IPPODROM!J7+IPPODROM!J8 -> 0 | M34: =+IPPODROM!M7+IPPODROM!M8 -> 0 | N34: =+IPPODROM!N7+IPPODROM!N8 -> 2
B35: 5 | C35: АРХИТЕКТОР / MIMAR | D35: =+N35 -> 1 | E35: =L35 -> 0 | F35: =M35 -> 0 | G35: =D35-E35-F35 -> 1 | K35: =+G35 -> 1 | L35: =+IPPODROM!J9 -> 0 | M35: =+IPPODROM!M9 -> 0 | N35: =+IPPODROM!N9 -> 1
B36: 6 | C36: СМЕТНЫЙ ОТДЕЛ | D36: =+N36 -> 2 | E36: =L36 -> 0 | F36: =M36 -> 0 | G36: =D36-E36-F36 -> 2 | K36: =+G36 -> 2 | L36: =+IPPODROM!J10+IPPODROM!J11 -> 0 | M36: =+IPPODROM!M10+IPPODROM!M11 -> 0 | N36: =+IPPODROM!N10+IPPODROM!N11 -> 2
B37: 7 | C37: ИНЖЕНЕР СТРОИТЕЛЬ / INSAAT TEKNIKERI | D37: =+N37 -> 8 | E37: =L37 -> 0 | F37: =M37 -> 0 | G37: =D37-E37-F37 -> 8 | K37: =+G37 -> 8 | L37: =+IPPODROM!J12++IPPODROM!J13+IPPODROM!J15+IPPODROM!J16+IPPODROM!J17+IPPODROM!J14+IPPODROM!J25+IPPODROM!J18+IPPODROM!J19 -> 0 | M37: =+IPPODROM!M12++IPPODROM!M13+IPPODROM!M15+IPPODROM!M16+IPPODROM!M17+IPPODROM!M14+IPPODROM!M18+IPPODROM!M19 -> 0 | N37: =+IPPODROM!N12+IPPODROM!N13+IPPODROM!N15+IPPODROM!N16+IPPODROM!N17+IPPODROM!N14+IPPODROM!N18+IPPODROM!N19 -> 8
B38: 8 | C38: ИНЖЕНЕР ЭЛЕКТРИК / ELECTRICAL CHIEF | D38: =+N38 -> 6 | E38: =L38 -> 0 | F38: =M38 -> 0 | G38: =D38-E38-F38 -> 6 | K38: =+G38 -> 6 | L38: =+IPPODROM!J20+IPPODROM!J21+IPPODROM!J22+IPPODROM!J23+IPPODROM!J25 -> 0 | M38: =+IPPODROM!M20+IPPODROM!M21+IPPODROM!M22+IPPODROM!M23+IPPODROM!M25 -> 0 | N38: =+IPPODROM!N20+IPPODROM!N21+IPPODROM!N22+IPPODROM!N23+IPPODROM!N25+IPPODROM!K24 -> 6
B39: 9 | C39: ИНЖЕНЕР МЕХАНИК / MECHANICAL CHIEF | D39: =+N39 -> 6 | E39: =L39 -> 0 | F39: =M39 -> 2 | G39: =D39-E39-F39 -> 4 | K39: =+G39 -> 4 | L39: =IPPODROM!J18+IPPODROM!J26+IPPODROM!J27+IPPODROM!J28+IPPODROM!J31 -> 0 | M39: =+IPPODROM!M26+IPPODROM!M27+IPPODROM!M27+IPPODROM!M28+IPPODROM!M29+IPPODROM!M30+IPPODROM!M31 -> 2 | N39: =+IPPODROM!N26+IPPODROM!N27+IPPODROM!N28+IPPODROM!N29+IPPODROM!N30+IPPODROM!N31 -> 6
B40: 10 | C40: монтажник | D40: 1 | E40: =L40 -> 0 | F40: =M40 -> 1 | G40: =D40-E40-F40 -> 0 | K40: =+G40 -> 0 | L40: =+IPPODROM!J32 -> 0 | M40: =+IPPODROM!M32 -> 1 | N40: =+IPPODROM!N32 -> 1
B41: 11 | C41: ИНЖЕНЕР ПТО / DESIGN TECH.ENGINEER | D41: =+N41 -> 9 | E41: =L41 -> 0 | F41: =M41 -> 0 | G41: =D41-E41-F41 -> 9 | K41: =+G41 -> 9 | L41: =+IPPODROM!J28+IPPODROM!J34+IPPODROM!J35+IPPODROM!J37+IPPODROM!J40+IPPODROM!J41+IPPODROM!J38+IPPODROM!J33+IPPODROM!J36+IPPODROM!J39 -> 0 | M41: =+IPPODROM!M33+IPPODROM!M34+IPPODROM!M35+IPPODROM!M36+IPPODROM!M37+IPPODROM!M38+IPPODROM!M39+IPPODROM!M40+IPPODROM!M41 -> 0 | N41: =+IPPODROM!N28+IPPODROM!N34+IPPODROM!N35+IPPODROM!N37+IPPODROM!N40+IPPODROM!N41+IPPODROM!N38+IPPODROM!N33+IPPODROM!N36 -> 9
...

Sheet IPPODROM
A1: Монотекстрой-Ипподром | I1: =+CHOOSE(WEEKDAY(I2,2),"Понедельник","Вторник","Среда","Четверг","Пятница","Суббота","Воскресенье.") -> Пятница | J1: yok | K1: gunduz | L1: geca | M1: dis | N1: sayi
A2: NO | B2: КОД | C2: Ofis Personel / Итр | D2: ФИО / isim soyad | F2: NM | G2: FM | H2: Общий | I2: 46122
A3: 1 | B3: 2037 | C3: Bora Poyraz | D3: Пойраз Бора | E3: PROJE MUDURU | F3: X | K3: 1 | N3: 1
A4: 2 | B4: 2035 | C4: Samet Selcuk | D4: Селчук Самет | E4: PROJE MUDURU | F4: X | K4: 1 | N4: 1
A5: 3 | B5: 2793 | C5: AndreyPirazyan | D5: Пиразян Андрей Генндьевич | E5: PROJE MUDURU | F5: X | K5: 1 | N5: 1
A6: 4 | B6: 2799 | C6: Dimitriy Guskov | D6: Гуськов Дмитрий Александрович | E6: SANTIYE SEFI | F6: 0 | I6: DIS GOREV ИнтерРАО | K6: 0 | M6: 1 | N6: 1
A7: 5 | B7: 2003 | C7: Gokay Kabakci | D7: Кабакджы Гокай | E7: TEKNIK OFIS SEFI | F7: X | K7: 1 | N7: 1
A8: 6 | B8: 2008 | C8: Tolga Topal | D8: Топал Толга | E8: TEKNIK OFIS MUHENDISI | F8: X | K8: 1 | N8: 1
A9: 7 | B9: 2022 | C9: Nejmeddin Aydin | D9: Айдын Неджмедин | E9: BAS MIMAR | F9: X | K9: 1 | N9: 1
A10: 8 | B10: DG | C10: Ekaterina Stakhovskaya | D10: Стакховская Екатерина | E10: SMETA MUHENDISI | F10: X | I10: DIS GOREV NIJNIY NOVGORODDEN GELDI | K10: 1 | N10: 1
A11: 9 | B11: 2797 | C11: Tatyana Prikhodko | D11: Приходько Татьяна Михайловна | E11: SMETA MUHENDISI | F11: X | K11: 1 | N11: 1
A12: 10 | B12: 2027 | C12: Fatih Cakir | D12: Чакыр Фатих | E12: INSAAT TEKNIKERI (SAHA SEFI) | F12: X | K12: 1 | N12: 1
A13: 11 | B13: 2739 | C13: Akbaraly Kambaraly Uulu | D13: Камбаралы уулу Акбаралы | E13: SAHA MUHENDISI | F13: X | K13: 1 | N13: 1
A14: 12 | B14: 2033 | C14: Oner Sahin | D14: Шахин Онер | E14: SAHA MUHENDISI | F14: X | K14: 1 | N14: 1
A15: 13 | B15: 2728 | C15: Rodion Datsyuk | D15: Дацюк Родион | E15: INSAAT MUHENDISI | F15: X | K15: 1 | N15: 1
A16: 14 | B16: 2782 | C16: Gurgen Vansyan | D16: Вансян Гурген | E16: INSAAT MUHENDISI | F16: X | K16: 1 | N16: 1
A17: 15 | B17: 2778 | C17: Andrey Djabarov | D17: Джабаров Андрей Русланович | E17: INSAAT MUHENDISI | F17: X | K17: 1 | N17: 1
A18: 16 | B18: 2026 | C18: Erol Tufan Tural | D18: Турал Эрол Туфан | E18: MAKINE TEKNIKERI | F18: X | K18: 1 | N18: 1
A19: 17 | B19: DG | C19: Ozgur Calis | D19: Чалыш Озгюр | E19: MAKINE TEKNIKERI | F19: X | I19: DIS GOREV ZELENOGRADDAN GELDI | K19: 1 | N19: 1
A20: 18 | B20: 2028 | C20: Serdar Deha Erozbek | D20: Эрозбек Сердар Деха | E20: ELEKTRIK KISIM SEFI | F20: X | K20: 1 | N20: 1
A21: 19 | B21: 2023 | C21: Yilmaz Karakus | D21: Каракуш Йылмаз | E21: ELEKTRIK MUHENDISI | F21: X | K21: 1 | N21: 1
A22: 20 | B22: 2735 | C22: Ilya Melnichenko | D22: Мелниченко Иля | E22: ELEKTRIK ZAYIF AKIM MUHENDISI | F22: X | K22: 1 | N22: 1
A23: 21 | B23: 2774 | C23: Vsevolod Filippov | D23: Филиппов Всеволод Владимирович | E23: ELEKTRIK P.T.O MUHENDISI | F23: X | K23: 1 | N23: 1
A24: 22 | B24: DG | C24: Lyubov Tihonova | D24: Тихонова Любовь Игоревна | E24: ELEKTRIK P.T.O MUHENDISI | F24: X | I24: DIS GOREV SKOLKOVODAN GELDI | K24: 1 | N24: 1
A25: 23 | B25: 2794 | C25: Chyngyz Sharsheev | D25: Шаршеев Чынгыз | E25: ELEKTRIK P.T.O MUHENDISI | F25: X | K25: 1 | N25: 1
A26: 24 | B26: 2039 | C26: Eyup Yilldiz | D26: Йылдыз Эйуп | E26: MEKANIK TEKNİKERİ | F26: X | K26: 1 | N26: 1
A27: 25 | B27: 2790 | C27: Arystanbek Munarbek Uulu | D27: Мунарбек уулу Арыстанбек | E27: PTO (MEKANIK) MUHENDISI | F27: X | K27: 1 | N27: 1
A28: 26 | B28: 2025 | C28: Serdar Yaylali | D28: Йайлалы Сердар Мустафаевич | E28: PTO (MEKANIK) MUHENDISI | F28: 0 | I28: DIS GOREV ИнтерРАО | K28: 0 | M28: 1 | N28: 1
A29: 27 | B29: 2801 | C29: Mihayil Ganin | D29: Ганин Михаил Анатольевич | E29: PTO (MEKANIK) MUHENDISI | F29: 0 | I29: DIS GOREV SKOLKOVO | K29: 0 | M29: 1 | N29: 1
A30: 28 | B30: 2047 | C30: Berkan Saygili | D30: Сайгили Беркан | E30: MEKANIK SAHA MUHENDISI | F30: X | K30: 1 | N30: 1
A31: 29 | B31: 2776 | C31: Kazbek Basiev | D31: Басиев Казбек Русланович | E31: MEKANIK MUHENDISI | F31: X | K31: 1 | N31: 1
A32: 30 | B32: 2029 | C32: Ali Kiremitci | D32: Киремитчи Али | E32: MONTAJCI | F32: 0 | I32: DIS GOREV SKOLKOVO | K32: 0 | M32: 1 | N32: 1
A33: 31 | B33: 2788 | C33: Dimitriy Sokolov | D33: Соколов Дмитрий Александрович | E33: P.T.O SEFI | F33: X | K33: 1 | N33: 1
A34: 32 | B34: 2705 | C34: Oleg Li | D34: Ли Олег | E34: P.T.O MUHENDISI | F34: X | K34: 1 | N34: 1
A35: 33 | B35: 2775 | C35: Aleksandr Bekirov | D35: Бекиров Александр Сергеевич | E35: P.T.O MUHENDISI | F35: X | K35: 1 | N35: 1
A36: 34 | B36: 2772 | C36: Markel Mareev | D36: Мареев Маркел Маратович | E36: P.T.O MUHENDISI | F36: X | K36: 1 | N36: 1
A37: 35 | B37: 2785 | C37: Artom Krylov | D37: Крылов Артём Петрович | E37: P.T.O MUHENDISI | F37: X | K37: 1 | N37: 1
A38: 36 | B38: 2789 | C38: Diana Ayvazyan | D38: Айвазян Диана Айказовна | E38: P.T.O MUHENDISI | F38: X | K38: 1 | N38: 1
A39: 37 | B39: 2796 | C39: Islam Albogachiev | D39: Албогачиев Ислам Магомедович | E39: P.T.O MUHENDISI | F39: X | K39: 1 | N39: 1
A40: 38 | B40: 2786 | C40: Nuryagdy Kerimov | D40: Керимов Нурягды | E40: P.T.O YARDAMCISI | F40: X | K40: 1 | N40: 1
...

Sheet Лист1

Sheet Лист2
C3: 4267 | D3: Asrorjon Ergashev | E3: Эргашев Асрорджон Ахматович | F3: INCE ISLER EKIPBASI | G3: Х | J3: SAHA | L3: 1
C4: 4268 | D4: Farkhod Kobilkhujaev | E4: Кобилхуджаев Фарход Рустамович | F4: INCE ISLER EKIPBASI | G4: Х | J4: SAHA | L4: 1
C5: 5134 | D5: Bunyod Dilmurotov | E5: Дилмуротов Бунёд Бобомурод Угли | F5: INCE ISLER EKIPBASI | G5: 0 | J5: DIS GOREV IKB | L5: 0 | N5: 1
C6: 5268 | D6: Mukhammadaziz Kodiraliev | E6: Кодиралиев Мухаммадазиз Сохибжон Угли | F6: INCE ISLER EKIPBASI | G6: 0 | J6: DIS GOREV ИнтерРАО | L6: 0 | N6: 1
C7: 5652 | D7: Kholmirza Meyliev | E7: Мейлиев Холмирза Асадулло Угли | F7: ALCI BOYA USTASI | G7: 7.5 | H7: 2.5 | I7: =IF(H7>0,(H7*1.5)+G7,"YOK") -> 11.25 | J7: TRIBUNA TAVAN SIVA IMALATI | L7: 1
C8: 4278 | D8: Muso Muhabbatov | E8: Мухаббатов Мусо Саъдуллоевич | F8: ALCI BOYA USTASI | G8: 7.5 | H8: 2.5 | I8: =IF(H8>0,(H8*1.5)+G8,"YOK") -> 11.25 | J8: TRIBUNA TAVAN SIVA IMALATI | L8: 1
C9: 5271 | D9: Khalimjon Akhmedov | E9: Ахмедов Халимжон Расулджонович | F9: ALCIPAN USTASI | G9: 7.5 | H9: 2.5 | I9: =IF(H9>0,(H9*1.5)+G9,"YOK") -> 11.25 | J9: TRIBUNA TAVAN SIVA IMALATI | L9: 1
C10: 5047 | D10: Saidburhon Abdulloev | E10: Абдуллоев Саидбурхон Абдурахмонович | F10: DUVAR USTASI | G10: 7.5 | H10: 2.5 | I10: =IF(H10>0,(H10*1.5)+G10,"YOK") -> 11.25 | J10: TRIBUNA TAVAN SIVA IMALATI | L10: 1
C11: 5424 | D11: Umedjon Davlatov | E11: Давлатов Умеджон Хусейнович | F11: DUVAR USTASI | G11: 7.5 | H11: 2.5 | I11: =IF(H11>0,(H11*1.5)+G11,"YOK") -> 11.25 | J11: TRIBUNA TAVAN SIVA IMALATI | L11: 1
C12: 4633 | D12: Hojisalmon Usmonshoev | E12: Усмоншоев Ходжисалмон Хошимджонович | F12: DUVAR USTASI | G12: 7.5 | H12: 2.5 | I12: =IF(H12>0,(H12*1.5)+G12,"YOK") -> 11.25 | J12: ARENA DUVAR SILIM VE BOYASI | L12: 1
C13: 5445 | D13: Dustmurod Gadoev | E13: Гадоев Дустмурод Эмомджонович | F13: DUVAR USTASI | G13: 7.5 | H13: 2.5 | I13: =IF(H13>0,(H13*1.5)+G13,"YOK") -> 11.25 | J13: ARENA DUVAR SILIM VE BOYASI | L13: 1
C14: 4998 | D14: Safarali Rahmonov | E14: Рахмонов Сафарали Махсудбекович | F14: DUVAR USTASI | G14: 7.5 | H14: 2.5 | I14: =IF(H14>0,(H14*1.5)+G14,"YOK") -> 11.25 | J14: ARENA DUVAR SILIM VE BOYASI | L14: 1
C15: 5715 | D15: Samariddin Bobobekov | E15: Бобобеков Самариддин Абилкосим Угли | F15: DUVAR USTASI | G15: 7.5 | H15: 2.5 | I15: =IF(H15>0,(H15*1.5)+G15,"YOK") -> 11.25 | J15: ARENA DUVAR SILIM VE BOYASI | L15: 1
C16: 5713 | D16: Jasur Murodov | E16: Муродов Жасур Ирискулович | F16: DUVAR USTASI | G16: 7.5 | H16: 2.5 | I16: =IF(H16>0,(H16*1.5)+G16,"YOK") -> 11.25 | J16: ARENA DUVAR SILIM VE BOYASI | L16: 1
C17: 5719 | D17: Asadbek Karimov | E17: Каримов Асадбек Давлат Угли | F17: DUVAR USTASI | G17: 7.5 | H17: 2.5 | I17: =IF(H17>0,(H17*1.5)+G17,"YOK") -> 11.25 | J17: ARENA DUVAR SILIM VE BOYASI | L17: 1
C18: 5105 | D18: Nazliddin Muzaffarov | E18: Музаффаров Назриддин Назюллоевич | F18: DUVAR USTASI | G18: 7.5 | H18: 2.5 | I18: =IF(H18>0,(H18*1.5)+G18,"YOK") -> 11.25 | J18: 1 KAT SOKUL DUVAR IMALATI | L18: 1
C19: 4638 | D19: Shahzod Murodullaev | E19: Муродуллаев Шахзод Акмал Угли | F19: DUVAR USTASI | G19: 7.5 | H19: 2.5 | I19: =IF(H19>0,(H19*1.5)+G19,"YOK") -> 11.25 | J19: 1 KAT SOKUL DUVAR IMALATI | L19: 1
C20: 4635 | D20: Abubakr Fayziddinov | E20: Файзиддинов Абубакр Садирович | F20: DUVAR USTASI | G20: 0 | H20: 0 | I20: =IF(H20>0,(H20*1.5)+G20,"YOK") -> YOK | J20: ISE CIKMADI | K20: 1 | L20: 0
C21: 5714 | D21: Asliddin Arifjanov | E21: Арифжанов Аслиддин Дувланович | F21: DUVAR USTASI | G21: 0 | H21: 0 | I21: =IF(H21>0,(H21*1.5)+G21,"YOK") -> YOK | J21: ISE CIKMADI | K21: 1 | L21: 0
C22: 4687 | D22: Mustafo Rakhmonov | E22: Рахмонов Мустафо Сафаралиевич | F22: SAPCI | G22: 7.5 | H22: 2.5 | I22: =IF(H22>0,(H22*1.5)+G22,"YOK") -> 11.25 | J22: ARENA DUVAR SILIM VE BOYASI | L22: 1
C23: 5270 | D23: Ummatali Mavlonov | E23: Мавлонов Умматали Рахманалиевич | F23: SERAMIK USTASI | G23: 7.5 | H23: 2.5 | I23: =IF(H23>0,(H23*1.5)+G23,"YOK") -> 11.25 | J23: FASAD BETON VE DUVAR DEMONTAC | L23: 1
C24: 4475 | D24: Ibrokhimdjon Saiburkhonov | E24: Сайбурхонов Иброхимджон Солехович | F24: SERAMIK USTASI | G24: 7.5 | H24: 2.5 | I24: =IF(H24>0,(H24*1.5)+G24,"YOK") -> 11.25 | J24: FASAD BETON VE DUVAR DEMONTAC | L24: 1
C25: 4601 | D25: Adilbek Khalmuratov | E25: Халмуратов Адилбек Аширбаевич | F25: SERAMIK USTASI | G25: 7.5 | H25: 2.5 | I25: =IF(H25>0,(H25*1.5)+G25,"YOK") -> 11.25 | J25: ATAPLENI YERLAR SIVA IMALATI | L25: 1
C26: 5570 | D26: Ruzimbay Djumashev | E26: Джумашев Рузимбай Султанович | F26: SERAMIK USTASI | G26: 7.5 | H26: 2.5 | I26: =IF(H26>0,(H26*1.5)+G26,"YOK") -> 11.25 | J26: ARENA DUVAR SILIM VE BOYASI | L26: 1
C27: 4374 | D27: Farkhod Allabergenov | E27: Аллабергенов Фархад Розибаевич | F27: SERAMIK USTASI | G27: 7.5 | H27: 2.5 | I27: =IF(H27>0,(H27*1.5)+G27,"YOK") -> 11.25 | J27: ARENA DUVAR SILIM VE BOYASI | L27: 1
C28: 4400 | D28: Suhrob Kobilhujaev | E28: Кобилхуджаев Сухроб Рустамович | F28: SERAMIK USTASI | G28: 7.5 | H28: 2.5 | I28: =IF(H28>0,(H28*1.5)+G28,"YOK") -> 11.25 | J28: ARENA DUVAR SILIM VE BOYASI | L28: 1
C29: DG | D29: Hojivali Badiev | E29: Бадиев Ходживали Давлатбекович | F29: SERAMIK USTASI | G29: 7.5 | H29: 2.5 | I29: =IF(H29>0,(H29*1.5)+G29,"YOK") -> 11.25 | J29: DIS GOREV ИнтерРАОDEN GELDI | L29: 1
C30: 5242 | D30: Pardali Sherkhonov | E30: Шерхонов Пардали Давлатович | F30: SIVACI | G30: 7.5 | H30: 2.5 | I30: =IF(H30>0,(H30*1.5)+G30,"YOK") -> 11.25 | J30: FASAD BETON VE DUVAR DEMONTAC | L30: 1
C31: 5451 | D31: Khursand Matyokubov | E31: Матёкубов Хурсанд Кодирович | F31: SIVACI | G31: 7.5 | H31: 2.5 | I31: =IF(H31>0,(H31*1.5)+G31,"YOK") -> 11.25 | J31: FASAD BETON VE DUVAR DEMONTAC | L31: 1
C32: 5454 | D32: Murodbek Madrimov | E32: Мадримов Муродбек Комилжонович | F32: SIVACI | G32: 7.5 | H32: 2.5 | I32: =IF(H32>0,(H32*1.5)+G32,"YOK") -> 11.25 | J32: FASAD BETON VE DUVAR DEMONTAC | L32: 1
C33: 5577 | D33: Amirbek Safarov | E33: Сафаров Амирбек Абдумуталибович | F33: SIVACI | G33: 7.5 | H33: 2.5 | I33: =IF(H33>0,(H33*1.5)+G33,"YOK") -> 11.25 | J33: FASAD BETON VE DUVAR DEMONTAC | L33: 1
C34: 5378 | D34: Anvar Muminov | E34: Муминов Анвар Азимович | F34: SIVACI | G34: 7.5 | H34: 2.5 | I34: =IF(H34>0,(H34*1.5)+G34,"YOK") -> 11.25 | J34: FASAD BETON VE DUVAR DEMONTAC | L34: 1
C35: 5272 | D35: Azizbek Nabijonov | E35: Набижонов Азизбек Хурсандали Угли | F35: SIVACI | G35: 7.5 | H35: 2.5 | I35: =IF(H35>0,(H35*1.5)+G35,"YOK") -> 11.25 | J35: FASAD BETON VE DUVAR DEMONTAC | L35: 1
C36: 5198 | D36: Samariddin Safarov | E36: Сафаров Самариддин Сафаралиевич | F36: SIVACI | G36: 7.5 | H36: 2.5 | I36: =IF(H36>0,(H36*1.5)+G36,"YOK") -> 11.25 | J36: FASAD BETON VE DUVAR DEMONTAC | L36: 1
C37: 5200 | D37: Saydali Holboboev | E37: Холбобоев Сайдали Тайлонович | F37: SIVACI | G37: 7.5 | H37: 2.5 | I37: =IF(H37>0,(H37*1.5)+G37,"YOK") -> 11.25 | J37: FASAD BETON VE DUVAR DEMONTAC | L37: 1
C38: 5237 | D38: Nekruz Holmadzoda | E38: Холмадзода Некруз Хасан | F38: SIVACI | G38: 7.5 | H38: 2.5 | I38: =IF(H38>0,(H38*1.5)+G38,"YOK") -> 11.25 | J38: FASAD BETON VE DUVAR DEMONTAC | L38: 1
C39: 4723 | D39: Elmurod Ortikov | E39: Ортиков Элмурод Камолбек Угли | F39: SIVACI | G39: 7.5 | H39: 2.5 | I39: =IF(H39>0,(H39*1.5)+G39,"YOK") -> 11.25 | J39: FASAD BETON VE DUVAR DEMONTAC | L39: 1
C40: 5716 | D40: Khudoyberdi Ortikov | E40: Ортиков Худайбекрди Абдишукурович | F40: SIVACI | G40: 0 | H40: 0 | I40: =IF(H40>0,(H40*1.5)+G40,"YOK") -> YOK | J40: ISE CIKMADI | K40: 1 | L40: 0
C41: 4634 | D41: Sirojidin Gafurov | E41: Гафуров Сирожидин Гиёсидинович | F41: SIVACI USTASI | G41: 7.5 | H41: 2.5 | I41: =IF(H41>0,(H41*1.5)+G41,"YOK") -> 11.25 | J41: FASAD BETON VE DUVAR DEMONTAC | L41: 1
C42: 4637 | D42: Avrosul Usmonshoev | E42: Усмоншоев Авросул Хошимович | F42: SIVACI USTASI | G42: 7.5 | H42: 2.5 | I42: =IF(H42>0,(H42*1.5)+G42,"YOK") -> 11.25 | J42: ATAPLENI YERLAR SIVA IMALATI | L42: 1
...

Sheet GUNLUK RAPOR
B1: Монотекстрой Ипподром | I1: =+IPPODROM!I2 -> 46122 | J1: =+IPPODROM!I1 -> Пятница
B2: EKIP | C2: EKIP SORUMLUSU | D2: TOPLAM MAVCUT | E2: TOPLAM CALISAN | F2: GUNDUZ CALISAN | G2: GECE CALISAN | H2: TOPLAM GELMEYEN | I2: SANTIYEYE GELMEYEN | J2: DIS GOREV
B3: IS GUVENLIK EKIBI | C3: ALEKSEY ANTIPOV | D3: =IPPODROM!A165 -> 19 | E3: =IPPODROM!K166 -> 14 | F3: =E3-G3 -> 13 | G3: =IPPODROM!L166 -> 1 | H3: =D3-E3 -> 5 | I3: =IPPODROM!J166 -> 4 | J3: =IPPODROM!M166 -> 1
B4: ELEKTRIK | C4: BEKZOD SAPAEV | D4: =IPPODROM!A381 -> 215 | E4: =IPPODROM!K382 -> 180 | F4: =E4-G4 -> 158 | G4: =IPPODROM!L382 -> 22 | H4: =D4-E4 -> 35 | I4: =IPPODROM!J382 -> 19 | J4: =IPPODROM!M382 -> 16
B5: MEKANIK-TESISAT | C5: OMER KAYA | D5: =IPPODROM!A461 -> 79 | E5: =IPPODROM!K462 -> 70 | F5: =E5-G5 -> 68 | G5: =IPPODROM!L462 -> 2 | H5: =D5-E5 -> 9 | I5: =IPPODROM!J462 -> 5 | J5: =IPPODROM!M462 -> 4 | AF5: =+E5+E6 -> 110
B6: MEKANIK-HAVALANDIRMA | C6: OMER KAYA | D6: =IPPODROM!A526 -> 64 | E6: =IPPODROM!K527 -> 40 | F6: =E6-G6 -> 37 | G6: =IPPODROM!L527 -> 3 | H6: =D6-E6 -> 24 | I6: =IPPODROM!J527 -> 4 | J6: =IPPODROM!M527 -> 20
B7: INCE ISLER BOGIBEK FATKULLIN | C7: BOGIBEK FATKULLIN | D7: =+IPPODROM!A651 -> 124 | E7: =IPPODROM!K652 -> 106 | F7: =E7-G7 -> 82 | G7: =IPPODROM!L652 -> 24 | H7: =D7-E7 -> 18 | I7: =IPPODROM!J652 -> 6 | J7: =IPPODROM!M652 -> 12 | AE7: ISDE | AF7: =SUM(E7:E25) -> 940
B8: INCE ISLER ASRORJON ERGASHEV | C8: ASRORJON ERGASHEV | D8: =IPPODROM!A699 -> 47 | E8: =IPPODROM!K700 -> 21 | F8: =E8-G8 -> 20 | G8: =IPPODROM!L700 -> 1 | H8: =D8-E8 -> 26 | I8: =IPPODROM!J700 -> 5 | J8: =IPPODROM!M700 -> 21 | AE8: YOK | AF8: =SUM(I7:I25) -> 69
B9: INCE ISLER ALISHER KADIROV | C9: ALISHER KADIROV | D9: =IPPODROM!A707 -> 7 | E9: =IPPODROM!K708 -> 0 | F9: =E9-G9 -> 0 | G9: =+IPPODROM!L708 -> 0 | H9: =D9-E9 -> 7 | I9: =IPPODROM!J708 -> 0 | J9: =IPPODROM!M708 -> 7 | AE9: DG | AF9: =SUM(J7:J25) -> 70
B10: INCE ISLER ABROR BERDIBAEV | C10: ABROR BERDIBAEV | D10: =+IPPODROM!A758 -> 50 | E10: =+IPPODROM!K759 -> 43 | F10: =E10-G10 -> 42 | G10: =+IPPODROM!L759 -> 1 | H10: =D10-E10 -> 7 | I10: =+IPPODROM!J759 -> 7 | J10: =+IPPODROM!M759 -> 0
B11: INCE ISLER FERUZ KULLIEV | C11: FERUZBEK KULLIEV | D11: =IPPODROM!A879 -> 120 | E11: =IPPODROM!K880 -> 108 | F11: =E11-G11 -> 107 | G11: =IPPODROM!L880 -> 1 | H11: =D11-E11 -> 12 | I11: =IPPODROM!J880 -> 6 | J11: =IPPODROM!M880 -> 6
B12: INCE ISLER-AKBARALI | C12: AKBARALI | D12: =IPPODROM!A910 -> 30 | E12: =IPPODROM!K911 -> 26 | F12: =E12-G12 -> 18 | G12: =IPPODROM!L911 -> 8 | H12: =D12-E12 -> 4 | I12: =IPPODROM!J911 -> 4 | J12: =IPPODROM!M911 -> 0
B13: INCE ISLER YUNUS TUNA | C13: YUNUS TUNA | D13: =IPPODROM!A992 -> 81 | E13: =IPPODROM!K993 -> 70 | F13: =E13-G13 -> 69 | G13: =IPPODROM!L993 -> 1 | H13: =D13-E13 -> 11 | I13: =IPPODROM!J993 -> 10 | J13: =IPPODROM!M993 -> 1
B14: INCE ISLER SUAT KURNAZ | C14: SUAT KURNAZ | D14: =IPPODROM!A1011 -> 18 | E14: =IPPODROM!K1012 -> 17 | F14: =E14-G14 -> 17 | G14: =IPPODROM!L1012 -> 0 | H14: =D14-E14 -> 1 | I14: =IPPODROM!J1012 -> 1 | J14: =IPPODROM!M1012 -> 0
B15: INCE ISLER ISMOIL KHUDOYBERGANOV | C15: ISMOIL KHUDOYBERGANOV | D15: =+IPPODROM!A1064 -> 52 | E15: =+IPPODROM!K1065 -> 45 | F15: =E15-G15 -> 45 | G15: =+IPPODROM!L1065 -> 0 | H15: =D15-E15 -> 7 | I15: =+IPPODROM!J1065 -> 7 | J15: =+IPPODROM!M1065 -> 0
B16: INCE ISLER RUSLAN RUZMETOV | C16: RUSLAN RUZMETOV | D16: =IPPODROM!A1075 -> 10 | E16: =IPPODROM!K1076 -> 10 | F16: =E16-G16 -> 10 | G16: =IPPODROM!L1076 -> 0 | H16: =D16-E16 -> 0 | I16: =IPPODROM!J1076 -> 0 | J16: =IPPODROM!M1076 -> 0
B17: INCE ISLER SARDOR KOCHKAROV | C17: SARDOR KOCHKAROV | D17: =+IPPODROM!A1243 -> 47 | E17: =+IPPODROM!K1244 -> 43 | F17: =E17-G17 -> 37 | G17: =+IPPODROM!L1244 -> 6 | H17: =D17-E17 -> 4 | I17: =+IPPODROM!J1244 -> 4 | J17: =+IPPODROM!M1244 -> 0
B18: CEPHECI EKIBI DJAMOLIDDIN ABDIEV | C18: DJAMOLIDDIN ABDIEV | D18: =IPPODROM!A1125 -> 49 | E18: =IPPODROM!K1126 -> 44 | F18: =E18-G18 -> 44 | G18: =IPPODROM!L1126 -> 0 | H18: =D18-E18 -> 5 | I18: =IPPODROM!J1126 -> 0 | J18: =IPPODROM!M1126 -> 5
B19: GENEL SAHA-BILAL KELLECI | C19: BILAL KELLECI | D19: =IPPODROM!A1168 -> 42 | E19: =IPPODROM!K1169 -> 42 | F19: =E19-G19 -> 26 | G19: =IPPODROM!L1169 -> 16 | H19: =D19-E19 -> 0 | I19: =IPPODROM!J1169 -> 0 | J19: =IPPODROM!M1169 -> 0
B20: GENEL SAHA-KENAN KURT | C20: KENAN KURT | D20: =IPPODROM!A1195 -> 26 | E20: =IPPODROM!K1196 -> 24 | F20: =E20-G20 -> 22 | G20: =IPPODROM!L1196 -> 2 | H20: =D20-E20 -> 2 | I20: =IPPODROM!J1196 -> 2 | J20: =IPPODROM!M1196 -> 0
B21: GENEL SAHA-MAKSUD ISMAYLOV | C21: MAKSUD ISMAYLOV | D21: =IPPODROM!A1288 -> 44 | E21: =IPPODROM!K1289 -> 43 | F21: =E21-G21 -> 35 | G21: =IPPODROM!L1289 -> 8 | H21: =D21-E21 -> 1 | I21: =IPPODROM!J1289 -> 1 | J21: =IPPODROM!M1289 -> 0
B22: GENEL SAHA ILHAN KOR | C22: ILHAN KOR | D22: =IPPODROM!A1332 -> 43 | E22: =IPPODROM!K1333 -> 41 | F22: =E22-G22 -> 36 | G22: =IPPODROM!L1333 -> 5 | H22: =D22-E22 -> 2 | I22: =IPPODROM!J1333 -> 2 | J22: =IPPODROM!M1333 -> 0
B23: GENEL SAHA-KAKHRAMON KURAMBAEV | C23: KAKHRAMON KURAMBAEV | D23: =IPPODROM!A1361 -> 28 | E23: =IPPODROM!K1362 -> 27 | F23: =E23-G23 -> 18 | G23: =IPPODROM!L1362 -> 9 | H23: =D23-E23 -> 1 | I23: =IPPODROM!J1362 -> 1 | J23: =IPPODROM!M1362 -> 0
B24: KALIPCI - DEMIRCI | C24: SAVAS YILMAZ | D24: =IPPODROM!A1419 -> 57 | E24: =IPPODROM!K1420 -> 52 | F24: =E24-G24 -> 43 | G24: =IPPODROM!L1420 -> 9 | H24: =D24-E24 -> 5 | I24: =IPPODROM!J1420 -> 5 | J24: =IPPODROM!M1420 -> 0
B25: KALIPCI - DEMIRCI | C25: HARUN AKDENIZ | D25: =IPPODROM!A1624 -> 204 | E25: =+IPPODROM!K1625 -> 178 | F25: =E25-G25 -> 144 | G25: =IPPODROM!L1625 -> 34 | H25: =D25-E25 -> 26 | I25: =+IPPODROM!J1625 -> 8 | J25: =+IPPODROM!M1625 -> 18
B26: DIREK TOPLAM | D26: =SUM(D3:D25) -> 1456 | E26: =SUM(E3:E25) -> 1244 | F26: =SUM(F3:F25) -> 1091 | G26: =SUM(G3:G25) -> 153 | H26: =SUM(H3:H25) -> 212 | I26: =SUM(I3:I25) -> 101 | J26: =SUM(J3:J25) -> 111
B27: ENDIREK VE HIZMETLI
B28: TEKNIK IDARE | D28: =IPPODROM!N57 -> 54 | E28: =IPPODROM!K57 -> 44 | F28: =E28-G28 -> 44 | G28: =IPPODROM!L57 -> 0 | H28: =D28-E28 -> 10 | I28: =IPPODROM!J57 -> 0 | J28: =IPPODROM!M57 -> 10
B29: TOPOGRAF | D29: =IPPODROM!A145 -> 21 | E29: =IPPODROM!K146 -> 21 | F29: =E29-G29 -> 21 | G29: =IPPODROM!L146 -> 0 | H29: =D29-E29 -> 0 | I29: =IPPODROM!J146 -> 0 | J29: =IPPODROM!M146 -> 0
B30: SOFOR | D30: =IPPODROM!A66 -> 9 | E30: =IPPODROM!K67 -> 6 | F30: =E30-G30 -> 6 | G30: =IPPODROM!L67 -> 0 | H30: =D30-E30 -> 3 | I30: =IPPODROM!J67 -> 0 | J30: =IPPODROM!M67 -> 3
B31: BEKCI | D31: =IPPODROM!A91 -> 24 | E31: =IPPODROM!K92 -> 17 | F31: =E31-G31 -> 9 | G31: =IPPODROM!L92 -> 8 | H31: =D31-E31 -> 7 | I31: =IPPODROM!J92 -> 0 | J31: =IPPODROM!M92 -> 7
B32: HIZMETLI | D32: =IPPODROM!A104 -> 12 | E32: =IPPODROM!K105 -> 11 | F32: =E32-G32 -> 10 | G32: =IPPODROM!L105 -> 1 | H32: =D32-E32 -> 1 | I32: =IPPODROM!J105 -> 0 | J32: =IPPODROM!M105 -> 1
B33: AMBARCI | D33: =IPPODROM!A123 -> 18 | E33: =IPPODROM!K124 -> 10 | F33: =E33-G33 -> 8 | G33: =IPPODROM!L124 -> 2 | H33: =D33-E33 -> 8 | I33: =IPPODROM!J124 -> 1 | J33: =IPPODROM!M124 -> 7
B34: ENDIREK TOPLAM | D34: =SUM(D28:D33) -> 138 | E34: =SUM(E28:E33) -> 109 | F34: =SUM(F28:F33) -> 98 | G34: =SUM(G28:G33) -> 11 | H34: =SUM(H28:H33) -> 29 | I34: =SUM(I28:I33) -> 1 | J34: =SUM(J28:J33) -> 28
B35: MONOTEKSTROY TOPLAM | D35: =+D34+D26 -> 1594 | E35: =+E34+E26 -> 1353 | F35: =+F34+F26 -> 1189 | G35: =+G34+G26 -> 164 | H35: =+H34+H26 -> 241 | I35: =+I34+I26 -> 102 | J35: =+J34+J26 -> 139
B37: ТЕХСТРОЙ | C37: 7977-344-43-36 | D37: 13 | E37: =D37 -> 13 | F37: =E37-G37 -> 13 | G37: 0 | H37: =D37-E37 -> 0
B38: АКВАСТРОЙ | C38: 7903-569-81-43 | D38: 57 | E38: =D38 -> 57 | F38: =E38-G38 -> 57 | G38: 0 | H38: =D38-E38 -> 0
B39: ООО «КВАНТГИДРОСТРОЙ» | C39: 7926-657-68-05 | D39: 72 | E39: =D39 -> 72 | F39: =E39-G39 -> 72 | G39: 0 | H39: =D39-E39 -> 0
B40: TASERON TOPLAM | D40: =SUM(D37:D39) -> 142 | E40: =SUM(E37:E39) -> 142 | F40: =SUM(F37:F39) -> 142 | G40: =SUM(G37:G39) -> 0 | H40: =SUM(H37:H39) -> 0 | I40: =SUM(I37:I39) -> 0 | J40: =SUM(J37:J39) -> 0
B42: GENEL TOPLAM | D42: =+D40+D35 -> 1736 | E42: =+E40+E35 -> 1495 | F42: =+F40+F35 -> 1331 | G42: =+G40+G35 -> 164 | H42: =+H40+H35 -> 241 | I42: =+I40+I35 -> 102 | J42: =+J40+J35 -> 139
...
